Workbook

Sheet k_fold_output
A1: model_name | B1: fold | C1: best_epoch | D1: validate_accuracy | E1: validate_precision | F1: validate_recall | G1: validate_f1 | H1: validate_auroc | I1: validate_average_precision | J1: validate_TN | K1: validate_FP | L1: validate_FN | M1: validate_TP | N1: test_accuracy | O1: test_precision | P1: test_recall | Q1: test_f1 | R1: test_auroc | S1: test_average_precision | T1: test_TN | U1: test_FP | V1: test_FN | W1: test_TP
A2: fresh-medicalnet-18 | B2: 1 | C2: 34 | D2: 0.84313726 | E2: 0.32417583 | F2: 0.49166667 | G2: 0.39072847 | H2: 0.82061577 | I2: 0.29654428 | J2: 930 | K2: 123 | L2: 61 | M2: 59 | N2: 0.86605781 | O2: 0.32258064 | P2: 0.54545456 | Q2: 0.4054054 | R2: 0.84757626 | S2: 0.37488148 | T2: 1078 | U2: 126 | V2: 50 | W2: 60
A3: fresh-medicalnet-18 | B3: 2 | C3: 24 | D3: 0.87479675 | E3: 0.38636363 | F3: 0.59649122 | G3: 0.46896553 | H3: 0.88657022 | I3: 0.47210073 | J3: 1008 | K3: 108 | L3: 46 | M3: 68 | N3: 0.83789957 | O3: 0.25821596 | P3: 0.5 | Q3: 0.34055728 | R3: 0.78593332 | S3: 0.29977146 | T3: 1046 | U3: 158 | V3: 55 | W3: 55
A4: fresh-medicalnet-18 | B4: 3 | C4: 36 | D4: 0.88258785 | E4: 0.34482759 | F4: 0.36036035 | G4: 0.35242289 | H4: 0.83903003 | I4: 0.36322302 | J4: 1065 | K4: 76 | L4: 71 | M4: 40 | N4: 0.87899542 | O4: 0.33986929 | P4: 0.47272727 | Q4: 0.39543727 | R4: 0.81479156 | S4: 0.29309142 | T4: 1103 | U4: 101 | V4: 58 | W4: 52
A5: fresh-medicalnet-18 | B5: 4 | C5: 34 | D5: 0.8768844 | E5: 0.37016574 | F5: 0.67000002 | G5: 0.47686833 | H5: 0.87851006 | I5: 0.55413777 | J5: 980 | K5: 114 | L5: 33 | M5: 67 | N5: 0.84474885 | O5: 0.29565218 | P5: 0.61818182 | Q5: 0.40000001 | R5: 0.85419059 | S5: 0.35654956 | T5: 1042 | U5: 162 | V5: 42 | W5: 68
A6: fresh-medicalnet-34 | B6: 1 | C6: 47 | D6: 0.86104006 | E6: 0.37572256 | F6: 0.54166669 | G6: 0.44368601 | H6: 0.8345679 | I6: 0.4107185 | J6: 945 | K6: 108 | L6: 55 | M6: 65 | N6: 0.86529678 | O6: 0.31693989 | P6: 0.5272727 | Q6: 0.39590445 | R6: 0.84269857 | S6: 0.35345256 | T6: 1079 | U6: 125 | V6: 52 | W6: 58
A7: fresh-medicalnet-34 | B7: 2 | C7: 46 | D7: 0.91707319 | E7: 0.57317072 | F7: 0.41228071 | G7: 0.47959185 | H7: 0.88806361 | I7: 0.51720136 | J7: 1081 | K7: 35 | L7: 67 | M7: 47 | N7: 0.89726025 | O7: 0.32394367 | P7: 0.2090909 | Q7: 0.25414366 | R7: 0.78586531 | S7: 0.27040511 | T7: 1156 | U7: 48 | V7: 87 | W7: 23
A8: fresh-medicalnet-34 | B8: 3 | C8: 22 | D8: 0.88658148 | E8: 0.37190083 | F8: 0.4054054 | G8: 0.38793105 | H8: 0.84649146 | I8: 0.33777294 | J8: 1065 | K8: 76 | L8: 66 | M8: 45 | N8: 0.87975645 | O8: 0.30645162 | P8: 0.34545454 | Q8: 0.32478634 | R8: 0.81576556 | S8: 0.30284184 | T8: 1118 | U8: 86 | V8: 72 | W8: 38
A9: fresh-medicalnet-34 | B9: 4 | C9: 43 | D9: 0.92294806 | E9: 0.55714285 | F9: 0.38999999 | G9: 0.45882353 | H9: 0.86962527 | I9: 0.4858034 | J9: 1063 | K9: 31 | L9: 61 | M9: 39 | N9: 0.89117199 | O9: 0.24615385 | P9: 0.14545454 | Q9: 0.18285714 | R9: 0.83652973 | S9: 0.27166513 | T9: 1155 | U9: 49 | V9: 94 | W9: 16
A10: fresh-medicalnet-50 | B10: 1 | C10: 28 | D10: 0.89002556 | E10: 0.45945945 | F10: 0.42500001 | G10: 0.44155845 | H10: 0.83556497 | I10: 0.42802811 | J10: 993 | K10: 60 | L10: 69 | M10: 51 | N10: 0.89345509 | O10: 0.3828125 | P10: 0.44545454 | Q10: 0.41176471 | R10: 0.85384315 | S10: 0.37506282 | T10: 1125 | U10: 79 | V10: 61 | W10: 49
A11: fresh-medicalnet-50 | B11: 2 | C11: 9 | D11: 0.90894312 | E11: 0.51190478 | F11: 0.37719297 | G11: 0.43434343 | H11: 0.88175189 | I11: 0.45915222 | J11: 1075 | K11: 41 | L11: 71 | M11: 43 | N11: 0.90258753 | O11: 0.39024389 | P11: 0.29090908 | Q11: 0.33333334 | R11: 0.8528617 | S11: 0.33635324 | T11: 1154 | U11: 50 | V11: 78 | W11: 32
A12: fresh-medicalnet-50 | B12: 3 | C12: 18 | D12: 0.90575081 | E12: 0.45333335 | F12: 0.3063063 | G12: 0.36559141 | H12: 0.82869464 | I12: 0.39162976 | J12: 1100 | K12: 41 | L12: 77 | M12: 34 | N12: 0.9041096 | O12: 0.37096775 | P12: 0.2090909 | Q12: 0.26744187 | R12: 0.84774995 | S12: 0.32019734 | T12: 1165 | U12: 39 | V12: 87 | W12: 23
A13: fresh-medicalnet-50 | B13: 4 | C13: 16 | D13: 0.89782244 | E13: 0.40983605 | F13: 0.5 | G13: 0.45045045 | H13: 0.86980808 | I13: 0.52274638 | J13: 1022 | K13: 72 | L13: 50 | M13: 50 | N13: 0.90639269 | O13: 0.44144145 | P13: 0.44545454 | Q13: 0.44343892 | R13: 0.85299003 | S13: 0.40562862 | T13: 1142 | U13: 62 | V13: 61 | W13: 49
... A73: vivit_random_3ch | B73: 4 | C73: 45 | D73: 0.9154104 | E73: 0 | F73: 0 | G73: 0 | H73: 0.72410423 | I73: 0.21840052 | J73: 1093 | K73: 1 | L73: 100 | M73: 0 | N73: 0.91628617 | O73: 0 | P73: 0 | Q73: 0 | R73: 0.68302631 | S73: 0.14902006 | T73: 1204 | U73: 0 | V73: 110 | W73: 0

Sheet luna16_k_fold_output
A1: model_name | B1: fold | C1: test_accuracy | D1: test_precision | E1: test_recall | F1: test_f1 | G1: test_auroc | H1: test_average_precision | I1: test_TN | J1: test_FP | K1: test_FN | L1: test_TP
A2: fresh-medicalnet-18 | B2: 1 | C2: 0.69565219 | D2: 0.94736844 | E2: 0.39130434 | F2: 0.55384618 | G2: 0.81092805 | H2: 0.83184785 | I2: 338 | J2: 7 | K2: 196 | L2: 126
A3: fresh-medicalnet-18 | B3: 2 | C3: 0.66866565 | D3: 0.85314685 | E3: 0.37888199 | F3: 0.52473116 | G3: 0.75666571 | H3: 0.77139533 | I3: 324 | J3: 21 | K3: 200 | L3: 122
A4: fresh-medicalnet-18 | B4: 3 | C4: 0.61169416 | D4: 0.86206895 | E4: 0.23291926 | F4: 0.36674815 | G4: 0.75101274 | H4: 0.74560064 | I4: 333 | J4: 12 | K4: 247 | L4: 75
A5: fresh-medicalnet-18 | B5: 4 | C5: 0.70014995 | D5: 0.88125002 | E5: 0.43788821 | F5: 0.58506227 | G5: 0.78428298 | H5: 0.80389529 | I5: 326 | J5: 19 | K5: 181 | L5: 141
A6: fresh-medicalnet-34 | B6: 1 | C6: 0.69115442 | D6: 0.8918919 | E6: 0.40993789 | F6: 0.56170213 | G6: 0.79862279 | H6: 0.80966544 | I6: 329 | J6: 16 | K6: 190 | L6: 132
A7: fresh-medicalnet-34 | B7: 2 | C7: 0.57571214 | D7: 0.88235295 | E7: 0.13975155 | F7: 0.24128686 | G7: 0.74853724 | H7: 0.74480987 | I7: 339 | J7: 6 | K7: 277 | L7: 45
A8: fresh-medicalnet-34 | B8: 3 | C8: 0.66416794 | D8: 0.90163934 | E8: 0.3416149 | F8: 0.4954955 | G8: 0.81018096 | H8: 0.80914408 | I8: 333 | J8: 12 | K8: 212 | L8: 110
A9: fresh-medicalnet-34 | B9: 4 | C9: 0.58770615 | D9: 0.89830506 | E9: 0.16459627 | F9: 0.27821523 | G9: 0.75701684 | H9: 0.76895565 | I9: 339 | J9: 6 | K9: 269 | L9: 53
A10: fresh-medicalnet-50 | B10: 1 | C10: 0.64767617 | D10: 0.96774191 | E10: 0.27950311 | F10: 0.43373495 | G10: 0.78731662 | H10: 0.81632018 | I10: 342 | J10: 3 | K10: 232 | L10: 90
A11: fresh-medicalnet-50 | B11: 2 | C11: 0.57871062 | D11: 0.97674417 | E11: 0.13043478 | F11: 0.23013699 | G11: 0.77729768 | H11: 0.80045927 | I11: 344 | J11: 1 | K11: 280 | L11: 42
A12: fresh-medicalnet-50 | B12: 3 | C12: 0.57271361 | D12: 0.91111112 | E12: 0.12732919 | F12: 0.22343324 | G12: 0.7817986 | H12: 0.77736735 | I12: 341 | J12: 4 | K12: 281 | L12: 41
A13: fresh-medicalnet-50 | B13: 4 | C13: 0.60269862 | D13: 0.9130435 | E13: 0.19565217 | F13: 0.32225063 | G13: 0.78977406 | H13: 0.78692126 | I13: 339 | J13: 6 | K13: 259 | L13: 63
... A73: vivit_random_3ch | B73: 4 | C73: 0.51724136 | D73: 0 | E73: 0 | F73: 0 | G73: 0.60960484 | H73: 0.55841643 | I73: 345 | J73: 0 | K73: 322 | L73: 0

Sheet k_fold_2stage_output
A1: model_name | B1: fold | C1: best_epoch | D1: validate_accuracy | E1: validate_precision | F1: validate_recall | G1: validate_f1 | H1: validate_auroc | I1: validate_average_precision | J1: validate_TN | K1: validate_FP | L1: validate_FN | M1: validate_TP | N1: test_accuracy | O1: test_precision | P1: test_recall | Q1: test_f1 | R1: test_auroc | S1: test_average_precision | T1: test_TN | U1: test_FP | V1: test_FN | W1: test_TP
A2: medicalnet-18-2stage | B2: 1 | C2: 42 | D2: 0.86956519 | E2: 0.37956205 | F2: 0.43333334 | G2: 0.40466926 | H2: 0.83078504 | I2: 0.37758863 | J2: 968 | K2: 85 | L2: 68 | M2: 52 | N2: 0.88508373 | O2: 0.34351146 | P2: 0.40909091 | Q2: 0.37344399 | R2: 0.84165657 | S2: 0.32382387 | T2: 1118 | U2: 86 | V2: 65 | W2: 45
A3: medicalnet-18-2stage | B3: 2 | C3: 30 | D3: 0.90487802 | E3: 0.48739496 | F3: 0.50877196 | G3: 0.49785408 | H3: 0.89392722 | I3: 0.53801501 | J3: 1055 | K3: 61 | L3: 56 | M3: 58 | N3: 0.8866058 | O3: 0.34400001 | P3: 0.39090911 | Q3: 0.36595744 | R3: 0.83157659 | S3: 0.30148157 | T3: 1122 | U3: 82 | V3: 67 | W3: 43
A4: medicalnet-18-2stage | B4: 3 | C4: 49 | D4: 0.87060702 | E4: 0.32413793 | F4: 0.42342341 | G4: 0.3671875 | H4: 0.84429651 | I4: 0.34148261 | J4: 1043 | K4: 98 | L4: 64 | M4: 47 | N4: 0.8713851 | O4: 0.30201343 | P4: 0.40909091 | Q4: 0.34749034 | R4: 0.83736783 | S4: 0.33937109 | T4: 1100 | U4: 104 | V4: 65 | W4: 45
A5: medicalnet-18-2stage | B5: 4 | C5: 12 | D5: 0.92043549 | E5: 0.5316456 | F5: 0.41999999 | G5: 0.46927375 | H5: 0.87220299 | I5: 0.47592571 | J5: 1057 | K5: 37 | L5: 58 | M5: 42 | N5: 0.89041096 | O5: 0.29761904 | P5: 0.22727273 | Q5: 0.25773194 | R5: 0.83717155 | S5: 0.27202839 | T5: 1145 | U5: 59 | V5: 85 | W5: 25
A6: medicalnet-34-2stage | B6: 1 | C6: 37 | D6: 0.87297529 | E6: 0.37168142 | F6: 0.34999999 | G6: 0.36051503 | H6: 0.8400681 | I6: 0.34158233 | J6: 982 | K6: 71 | L6: 78 | M6: 42 | N6: 0.89269406 | O6: 0.37984496 | P6: 0.44545454 | Q6: 0.41004184 | R6: 0.81941265 | S6: 0.37349772 | T6: 1124 | U6: 80 | V6: 61 | W6: 49
A7: medicalnet-34-2stage | B7: 2 | C7: 26 | D7: 0.91300815 | E7: 0.53684211 | F7: 0.44736841 | G7: 0.48803827 | H7: 0.87250054 | I7: 0.47781157 | J7: 1072 | K7: 44 | L7: 63 | M7: 51 | N7: 0.90715373 | O7: 0.43181819 | P7: 0.34545454 | Q7: 0.38383839 | R7: 0.84232861 | S7: 0.35381767 | T7: 1154 | U7: 50 | V7: 72 | W7: 38
A8: medicalnet-34-2stage | B8: 3 | C8: 27 | D8: 0.88897765 | E8: 0.390625 | F8: 0.45045045 | G8: 0.41841003 | H8: 0.85670066 | I8: 0.42364055 | J8: 1063 | K8: 78 | L8: 61 | M8: 50 | N8: 0.87747335 | O8: 0.32413793 | P8: 0.42727274 | Q8: 0.36862746 | R8: 0.85246146 | S8: 0.35216168 | T8: 1106 | U8: 98 | V8: 63 | W8: 47
A9: medicalnet-34-2stage | B9: 4 | C9: 48 | D9: 0.91959798 | E9: 0.52702701 | F9: 0.38999999 | G9: 0.44827586 | H9: 0.8663162 | I9: 0.51733571 | J9: 1059 | K9: 35 | L9: 61 | M9: 39 | N9: 0.90334857 | O9: 0.33962265 | P9: 0.16363636 | Q9: 0.2208589 | R9: 0.79332525 | S9: 0.29745027 | T9: 1169 | U9: 35 | V9: 92 | W9: 18
A10: medicalnet-50-2stage | B10: 1 | C10: 31 | D10: 0.8806479 | E10: 0.41379312 | F10: 0.40000001 | G10: 0.40677965 | H10: 0.82097191 | I10: 0.3806558 | J10: 985 | K10: 68 | L10: 72 | M10: 48 | N10: 0.869102 | O10: 0.2651515 | P10: 0.31818181 | Q10: 0.28925619 | R10: 0.8172003 | S10: 0.28062385 | T10: 1107 | U10: 97 | V10: 75 | W10: 35
A11: medicalnet-50-2stage | B11: 2 | C11: 17 | D11: 0.90325201 | E11: 0.46913579 | F11: 0.33333334 | G11: 0.3897436 | H11: 0.87345147 | I11: 0.45601785 | J11: 1073 | K11: 43 | L11: 76 | M11: 38 | N11: 0.88508373 | O11: 0.26966292 | P11: 0.21818182 | Q11: 0.24120604 | R11: 0.83612204 | S11: 0.25460392 | T11: 1139 | U11: 65 | V11: 86 | W11: 24
A12: medicalnet-50-2stage | B12: 3 | C12: 37 | D12: 0.89536738 | E12: 0.375 | F12: 0.27027026 | G12: 0.31413612 | H12: 0.83259511 | I12: 0.31329495 | J12: 1091 | K12: 50 | L12: 81 | M12: 30 | N12: 0.90258753 | O12: 0.32692307 | P12: 0.15454546 | Q12: 0.20987654 | R12: 0.82312745 | S12: 0.26349485 | T12: 1169 | U12: 35 | V12: 93 | W12: 17
A13: medicalnet-50-2stage | B13: 4 | C13: 28 | D13: 0.90787268 | E13: 0.45901638 | F13: 0.56 | G13: 0.5045045 | H13: 0.88010973 | I13: 0.5590052 | J13: 1028 | K13: 66 | L13: 44 | M13: 56 | N13: 0.88203955 | O13: 0.35099337 | P13: 0.48181817 | Q13: 0.40613025 | R13: 0.83453643 | S13: 0.35391548 | T13: 1106 | U13: 98 | V13: 57 | W13: 53
... A29: vivit_pretrained-2stage | B29: 4 | C29: 36 | D29: 0.87018424 | E29: 0.35602096 | F29: 0.68000001 | G29: 0.46735394 | H29: 0.86933279 | I29: 0.41838086 | J29: 971 | K29: 123 | L29: 32 | M29: 68 | N29: 0.83713853 | O29: 0.2699115 | P29: 0.55454546 | Q29: 0.36309522 | R29: 0.8286469 | S29: 0.3456063 | T29: 1039 | U29: 165 | V29: 49 | W29: 61

Sheet k_fold_luna16db_output
A1: model_name | B1: fold | C1: best_epoch | D1: validate_accuracy | E1: validate_precision | F1: validate_recall | G1: validate_f1 | H1: validate_auroc | I1: validate_average_precision | J1: validate_TN | K1: validate_FP | L1: validate_FN | M1: validate_TP | N1: test_accuracy | O1: test_precision | P1: test_recall | Q1: test_f1 | R1: test_auroc | S1: test_average_precision | T1: test_TN | U1: test_FP | V1: test_FN | W1: test_TP
A2: medicalnet-18-luna16double | B2: 1 | C2: 5 | D2: 0.84910488 | E2: 0.34759358 | F2: 0.54166669 | G2: 0.42345276 | H2: 0.83869106 | I2: 0.33923212 | J2: 931 | K2: 122 | L2: 55 | M2: 65 | N2: 0.84094369 | O2: 0.28 | P2: 0.57272726 | Q2: 0.37611941 | R2: 0.84143013 | S2: 0.3052302 | T2: 1042 | U2: 162 | V2: 47 | W2: 63
A3: medicalnet-18-luna16double | B3: 2 | C3: 1 | D3: 0.902439 | E3: 0.43181819 | F3: 0.16666667 | G3: 0.24050634 | H3: 0.8888889 | I3: 0.39872855 | J3: 1091 | K3: 25 | L3: 95 | M3: 19 | N3: 0.91019785 | O3: 0.3888889 | P3: 0.12727273 | Q3: 0.19178082 | R3: 0.82495475 | S3: 0.31585291 | T3: 1182 | U3: 22 | V3: 96 | W3: 14
A4: medicalnet-18-luna16double | B4: 3 | C4: 25 | D4: 0.89696485 | E4: 0.41176471 | F4: 0.37837839 | G4: 0.3943662 | H4: 0.85655057 | I4: 0.38940865 | J4: 1081 | K4: 60 | L4: 69 | M4: 42 | N4: 0.88736683 | O4: 0.33035713 | P4: 0.33636364 | Q4: 0.33333334 | R4: 0.82619292 | S4: 0.33812523 | T4: 1129 | U4: 75 | V4: 73 | W4: 37
A5: medicalnet-18-luna16double | B5: 4 | C5: 30 | D5: 0.88190955 | E5: 0.3726708 | F5: 0.60000002 | G5: 0.45977011 | H5: 0.88812613 | I5: 0.52838147 | J5: 993 | K5: 101 | L5: 40 | M5: 60 | N5: 0.86605781 | O5: 0.31460676 | P5: 0.5090909 | Q5: 0.3888889 | R5: 0.81362873 | S5: 0.35676214 | T5: 1082 | U5: 122 | V5: 54 | W5: 56
A6: medicalnet-34-luna16double | B6: 1 | C6: 26 | D6: 0.85507244 | E6: 0.35955057 | F6: 0.53333336 | G6: 0.4295302 | H6: 0.83668095 | I6: 0.35470432 | J6: 939 | K6: 114 | L6: 56 | M6: 64 | N6: 0.87290716 | O6: 0.33714285 | P6: 0.53636366 | Q6: 0.41403508 | R6: 0.846421 | S6: 0.32204467 | T6: 1088 | U6: 116 | V6: 51 | W6: 59
A7: medicalnet-34-luna16double | B7: 2 | C7: 9 | D7: 0.90813011 | E7: 0.50877196 | F7: 0.25438598 | G7: 0.33918127 | H7: 0.87361664 | I7: 0.4041959 | J7: 1088 | K7: 28 | L7: 85 | M7: 29 | N7: 0.91019785 | O7: 0.43939394 | P7: 0.26363635 | Q7: 0.32954547 | R7: 0.84615684 | S7: 0.3392182 | T7: 1167 | U7: 37 | V7: 81 | W7: 29
A8: medicalnet-34-luna16double | B8: 3 | C8: 18 | D8: 0.90255588 | E8: 0.42253521 | F8: 0.27027026 | G8: 0.32967034 | H8: 0.84732068 | I8: 0.3773725 | J8: 1100 | K8: 41 | L8: 81 | M8: 30 | N8: 0.91019785 | O8: 0.44594595 | P8: 0.30000001 | Q8: 0.35869566 | R8: 0.87485659 | S8: 0.37571907 | T8: 1163 | U8: 41 | V8: 77 | W8: 33
A9: medicalnet-34-luna16double | B9: 4 | C9: 27 | D9: 0.92797321 | E9: 0.75 | F9: 0.20999999 | G9: 0.328125 | H9: 0.87060332 | I9: 0.49507189 | J9: 1087 | K9: 7 | L9: 79 | M9: 21 | N9: 0.91628617 | O9: 0.5 | P9: 0.16363636 | Q9: 0.24657534 | R9: 0.83798707 | S9: 0.32807037 | T9: 1186 | U9: 18 | V9: 92 | W9: 18
A10: medicalnet-50-luna16double | B10: 1 | C10: 15 | D10: 0.86615515 | E10: 0.35658914 | F10: 0.38333333 | G10: 0.3694779 | H10: 0.82415313 | I10: 0.37224281 | J10: 970 | K10: 83 | L10: 74 | M10: 46 | N10: 0.87823439 | O10: 0.33108109 | P10: 0.44545454 | Q10: 0.37984496 | R10: 0.84356689 | S10: 0.35837206 | T10: 1105 | U10: 99 | V10: 61 | W10: 49
A11: medicalnet-50-luna16double | B11: 2 | C11: 5 | D11: 0.91544718 | E11: 0.55102038 | F11: 0.47368422 | G11: 0.50943398 | H11: 0.88807142 | I11: 0.49678731 | J11: 1072 | K11: 44 | L11: 60 | M11: 54 | N11: 0.89345509 | O11: 0.34375 | P11: 0.30000001 | Q11: 0.32038835 | R11: 0.84879947 | S11: 0.32130381 | T11: 1141 | U11: 63 | V11: 77 | W11: 33
A12: medicalnet-50-luna16double | B12: 3 | C12: 30 | D12: 0.88977635 | E12: 0.38842976 | F12: 0.42342341 | G12: 0.40517241 | H12: 0.85340816 | I12: 0.408086 | J12: 1067 | K12: 74 | L12: 64 | M12: 47 | N12: 0.88127851 | O12: 0.33571428 | P12: 0.42727274 | Q12: 0.37599999 | R12: 0.83651471 | S12: 0.32147697 | T12: 1111 | U12: 93 | V12: 63 | W12: 47
A13: medicalnet-50-luna16double | B13: 4 | C13: 21 | D13: 0.91792297 | E13: 0.50925928 | F13: 0.55000001 | G13: 0.52884614 | H13: 0.88712066 | I13: 0.54123437 | J13: 1041 | K13: 53 | L13: 45 | M13: 55 | N13: 0.87823439 | O13: 0.3046875 | P13: 0.35454544 | Q13: 0.3277311 | R13: 0.84009361 | S13: 0.31534094 | T13: 1115 | U13: 89 | V13: 71 | W13: 39
... A29: vivit_pretrained-luna16double | B29: 4 | C29: 24 | D29: 0.90117252 | E29: 0.37142858 | F29: 0.25999999 | G29: 0.30588236 | H29: 0.84933281 | I29: 0.35585764 | J29: 1050 | K29: 44 | L29: 74 | M29: 26 | N29: 0.88964993 | O29: 0.30337077 | P29: 0.24545455 | Q29: 0.27135679 | R29: 0.81559956 | S29: 0.27385706 | T29: 1142 | U29: 62 | V29: 83 | W29: 27

Sheet Main Sheet
A1: Type | B1: Model | D1: Fold | E1: Best Epoch | F1: Validation | P1: Test | Z1: External
B2: Name | C2: Depth | F2: Accuracy | G2: Precision | H2: Recall | I2: F1 | J2: AUROC | K2: Average Precision | L2: Confusion Matrix | P2: Accuracy | Q2: Precision | R2: Recall | S2: F1 | T2: AUROC | U2: Average Precision | V2: Confusion Matrix | Z2: Accuracy | AA2: Precision | AB2: Recall | AC2: F1 | AD2: AUROC | AE2: Average Precision | AF2: Confusion Matrix
L3: TN | M3: FP | N3: FN | O3: TP | V3: TN | W3: FP | X3: FN | Y3: TP | AF3: TN | AG3: FP | AH3: FN | AI3: TP
A4: Fresh | B4: medicalnet | C4: 18 | D4: 1 | E4: =k_fold_output!C2 -> 34 | F4: =k_fold_output!D2 -> 0.84313726 | G4: =k_fold_output!E2 -> 0.32417583 | H4: =k_fold_output!F2 -> 0.49166667 | I4: =k_fold_output!G2 -> 0.39072847 | J4: =k_fold_output!H2 -> 0.82061577 | K4: =k_fold_output!I2 -> 0.29654428 | L4: =k_fold_output!J2 -> 930 | ... Y4: =k_fold_output!W2 -> 60 | Z4: =luna16_k_fold_output!C2 -> 0.69565219 | AA4: =luna16_k_fold_output!D2 -> 0.94736844 | AB4: =luna16_k_fold_output!E2 -> 0.39130434 | AC4: =luna16_k_fold_output!F2 -> 0.55384618 | AD4: =luna16_k_fold_output!G2 -> 0.81092805 | AE4: =luna16_k_fold_output!H2 -> 0.83184785 | AF4: =luna16_k_fold_output!I2 -> 338 | AG4: =luna16_k_fold_output!J2 -> 7 | ... AI4: =luna16_k_fold_output!L2 -> 126
D5: 2 | E5: =k_fold_output!C3 -> 24 | F5: =k_fold_output!D3 -> 0.87479675 | G5: =k_fold_output!E3 -> 0.38636363 | H5: =k_fold_output!F3 -> 0.59649122 | I5: =k_fold_output!G3 -> 0.46896553 | J5: =k_fold_output!H3 -> 0.88657022 | K5: =k_fold_output!I3 -> 0.47210073 | L5: =k_fold_output!J3 -> 1008 | ... Y5: =k_fold_output!W3 -> 55 | Z5: =luna16_k_fold_output!C3 -> 0.66866565 | AA5: =luna16_k_fold_output!D3 -> 0.85314685 | AB5: =luna16_k_fold_output!E3 -> 0.37888199 | AC5: =luna16_k_fold_output!F3 -> 0.52473116 | AD5: =luna16_k_fold_output!G3 -> 0.75666571 | AE5: =luna16_k_fold_output!H3 -> 0.77139533 | AF5: =luna16_k_fold_output!I3 -> 324 | AG5: =luna16_k_fold_output!J3 -> 21 | ... AI5: =luna16_k_fold_output!L3 -> 122
D6: 3 | E6: =k_fold_output!C4 -> 36 | F6: =k_fold_output!D4 -> 0.88258785 | G6: =k_fold_output!E4 -> 0.34482759 | H6: =k_fold_output!F4 -> 0.36036035 | I6: =k_fold_output!G4 -> 0.35242289 | J6: =k_fold_output!H4 -> 0.83903003 | K6: =k_fold_output!I4 -> 0.36322302 | L6: =k_fold_output!J4 -> 1065 | ... Y6: =k_fold_output!W4 -> 52 | Z6: =luna16_k_fold_output!C4 -> 0.61169416 | AA6: =luna16_k_fold_output!D4 -> 0.86206895 | AB6: =luna16_k_fold_output!E4 -> 0.23291926 | AC6: =luna16_k_fold_output!F4 -> 0.36674815 | AD6: =luna16_k_fold_output!G4 -> 0.75101274 | AE6: =luna16_k_fold_output!H4 -> 0.74560064 | AF6: =luna16_k_fold_output!I4 -> 333 | AG6: =luna16_k_fold_output!J4 -> 12 | ... AI6: =luna16_k_fold_output!L4 -> 75
D7: 4 | E7: =k_fold_output!C5 -> 34 | F7: =k_fold_output!D5 -> 0.8768844 | G7: =k_fold_output!E5 -> 0.37016574 | H7: =k_fold_output!F5 -> 0.67000002 | I7: =k_fold_output!G5 -> 0.47686833 | J7: =k_fold_output!H5 -> 0.87851006 | K7: =k_fold_output!I5 -> 0.55413777 | L7: =k_fold_output!J5 -> 980 | ... Y7: =k_fold_output!W5 -> 68 | Z7: =luna16_k_fold_output!C5 -> 0.70014995 | AA7: =luna16_k_fold_output!D5 -> 0.88125002 | AB7: =luna16_k_fold_output!E5 -> 0.43788821 | AC7: =luna16_k_fold_output!F5 -> 0.58506227 | AD7: =luna16_k_fold_output!G5 -> 0.78428298 | AE7: =luna16_k_fold_output!H5 -> 0.80389529 | AF7: =luna16_k_fold_output!I5 -> 326 | AG7: =luna16_k_fold_output!J5 -> 19 | ... AI7: =luna16_k_fold_output!L5 -> 141
C8: 34 | D8: 1 | E8: =k_fold_output!C6 -> 47 | F8: =k_fold_output!D6 -> 0.86104006 | G8: =k_fold_output!E6 -> 0.37572256 | H8: =k_fold_output!F6 -> 0.54166669 | I8: =k_fold_output!G6 -> 0.44368601 | J8: =k_fold_output!H6 -> 0.8345679 | K8: =k_fold_output!I6 -> 0.4107185 | L8: =k_fold_output!J6 -> 945 | ... Y8: =k_fold_output!W6 -> 58 | Z8: =luna16_k_fold_output!C6 -> 0.69115442 | AA8: =luna16_k_fold_output!D6 -> 0.8918919 | AB8: =luna16_k_fold_output!E6 -> 0.40993789 | AC8: =luna16_k_fold_output!F6 -> 0.56170213 | AD8: =luna16_k_fold_output!G6 -> 0.79862279 | AE8: =luna16_k_fold_output!H6 -> 0.80966544 | AF8: =luna16_k_fold_output!I6 -> 329 | AG8: =luna16_k_fold_output!J6 -> 16 | ... AI8: =luna16_k_fold_output!L6 -> 132
D9: 2 | E9: =k_fold_output!C7 -> 46 | F9: =k_fold_output!D7 -> 0.91707319 | G9: =k_fold_output!E7 -> 0.57317072 | H9: =k_fold_output!F7 -> 0.41228071 | I9: =k_fold_output!G7 -> 0.47959185 | J9: =k_fold_output!H7 -> 0.88806361 | K9: =k_fold_output!I7 -> 0.51720136 | L9: =k_fold_output!J7 -> 1081 | ... Y9: =k_fold_output!W7 -> 23 | Z9: =luna16_k_fold_output!C7 -> 0.57571214 | AA9: =luna16_k_fold_output!D7 -> 0.88235295 | AB9: =luna16_k_fold_output!E7 -> 0.13975155 | AC9: =luna16_k_fold_output!F7 -> 0.24128686 | AD9: =luna16_k_fold_output!G7 -> 0.74853724 | AE9: =luna16_k_fold_output!H7 -> 0.74480987 | AF9: =luna16_k_fold_output!I7 -> 339 | AG9: =luna16_k_fold_output!J7 -> 6 | ... AI9: =luna16_k_fold_output!L7 -> 45
D10: 3 | E10: =k_fold_output!C8 -> 22 | F10: =k_fold_output!D8 -> 0.88658148 | G10: =k_fold_output!E8 -> 0.37190083 | H10: =k_fold_output!F8 -> 0.4054054 | I10: =k_fold_output!G8 -> 0.38793105 | J10: =k_fold_output!H8 -> 0.84649146 | K10: =k_fold_output!I8 -> 0.33777294 | L10: =k_fold_output!J8 -> 1065 | ... Y10: =k_fold_output!W8 -> 38 | Z10: =luna16_k_fold_output!C8 -> 0.66416794 | AA10: =luna16_k_fold_output!D8 -> 0.90163934 | AB10: =luna16_k_fold_output!E8 -> 0.3416149 | AC10: =luna16_k_fold_output!F8 -> 0.4954955 | AD10: =luna16_k_fold_output!G8 -> 0.81018096 | AE10: =luna16_k_fold_output!H8 -> 0.80914408 | AF10: =luna16_k_fold_output!I8 -> 333 | AG10: =luna16_k_fold_output!J8 -> 12 | ... AI10: =luna16_k_fold_output!L8 -> 110
D11: 4 | E11: =k_fold_output!C9 -> 43 | F11: =k_fold_output!D9 -> 0.92294806 | G11: =k_fold_output!E9 -> 0.55714285 | H11: =k_fold_output!F9 -> 0.38999999 | I11: =k_fold_output!G9 -> 0.45882353 | J11: =k_fold_output!H9 -> 0.86962527 | K11: =k_fold_output!I9 -> 0.4858034 | L11: =k_fold_output!J9 -> 1063 | ... Y11: =k_fold_output!W9 -> 16 | Z11: =luna16_k_fold_output!C9 -> 0.58770615 | AA11: =luna16_k_fold_output!D9 -> 0.89830506 | AB11: =luna16_k_fold_output!E9 -> 0.16459627 | AC11: =luna16_k_fold_output!F9 -> 0.27821523 | AD11: =luna16_k_fold_output!G9 -> 0.75701684 | AE11: =luna16_k_fold_output!H9 -> 0.76895565 | AF11: =luna16_k_fold_output!I9 -> 339 | AG11: =luna16_k_fold_output!J9 -> 6 | ... AI11: =luna16_k_fold_output!L9 -> 53
C12: 50 | D12: 1 | E12: =k_fold_output!C10 -> 28 | F12: =k_fold_output!D10 -> 0.89002556 | G12: =k_fold_output!E10 -> 0.45945945 | H12: =k_fold_output!F10 -> 0.42500001 | I12: =k_fold_output!G10 -> 0.44155845 | J12: =k_fold_output!H10 -> 0.83556497 | K12: =k_fold_output!I10 -> 0.42802811 | L12: =k_fold_output!J10 -> 993 | ... Y12: =k_fold_output!W10 -> 49 | Z12: =luna16_k_fold_output!C10 -> 0.64767617 | AA12: =luna16_k_fold_output!D10 -> 0.96774191 | AB12: =luna16_k_fold_output!E10 -> 0.27950311 | AC12: =luna16_k_fold_output!F10 -> 0.43373495 | AD12: =luna16_k_fold_output!G10 -> 0.78731662 | AE12: =luna16_k_fold_output!H10 -> 0.81632018 | AF12: =luna16_k_fold_output!I10 -> 342 | AG12: =luna16_k_fold_output!J10 -> 3 | ... AI12: =luna16_k_fold_output!L10 -> 90
D13: 2 | E13: =k_fold_output!C11 -> 9 | F13: =k_fold_output!D11 -> 0.90894312 | G13: =k_fold_output!E11 -> 0.51190478 | H13: =k_fold_output!F11 -> 0.37719297 | I13: =k_fold_output!G11 -> 0.43434343 | J13: =k_fold_output!H11 -> 0.88175189 | K13: =k_fold_output!I11 -> 0.45915222 | L13: =k_fold_output!J11 -> 1075 | ... Y13: =k_fold_output!W11 -> 32 | Z13: =luna16_k_fold_output!C11 -> 0.57871062 | AA13: =luna16_k_fold_output!D11 -> 0.97674417 | AB13: =luna16_k_fold_output!E11 -> 0.13043478 | AC13: =luna16_k_fold_output!F11 -> 0.23013699 | AD13: =luna16_k_fold_output!G11 -> 0.77729768 | AE13: =luna16_k_fold_output!H11 -> 0.80045927 | AF13: =luna16_k_fold_output!I11 -> 344 | AG13: =luna16_k_fold_output!J11 -> 1 | ... AI13: =luna16_k_fold_output!L11 -> 42
D14: 3 | E14: =k_fold_output!C12 -> 18 | F14: =k_fold_output!D12 -> 0.90575081 | G14: =k_fold_output!E12 -> 0.45333335 | H14: =k_fold_output!F12 -> 0.3063063 | I14: =k_fold_output!G12 -> 0.36559141 | J14: =k_fold_output!H12 -> 0.82869464 | K14: =k_fold_output!I12 -> 0.39162976 | L14: =k_fold_output!J12 -> 1100 | ... Y14: =k_fold_output!W12 -> 23 | Z14: =luna16_k_fold_output!C12 -> 0.57271361 | AA14: =luna16_k_fold_output!D12 -> 0.91111112 | AB14: =luna16_k_fold_output!E12 -> 0.12732919 | AC14: =luna16_k_fold_output!F12 -> 0.22343324 | AD14: =luna16_k_fold_output!G12 -> 0.7817986 | AE14: =luna16_k_fold_output!H12 -> 0.77736735 | AF14: =luna16_k_fold_output!I12 -> 341 | AG14: =luna16_k_fold_output!J12 -> 4 | ... AI14: =luna16_k_fold_output!L12 -> 41
D15: 4 | E15: =k_fold_output!C13 -> 16 | F15: =k_fold_output!D13 -> 0.89782244 | G15: =k_fold_output!E13 -> 0.40983605 | H15: =k_fold_output!F13 -> 0.5 | I15: =k_fold_output!G13 -> 0.45045045 | J15: =k_fold_output!H13 -> 0.86980808 | K15: =k_fold_output!I13 -> 0.52274638 | L15: =k_fold_output!J13 -> 1022 | ... Y15: =k_fold_output!W13 -> 49 | Z15: =luna16_k_fold_output!C13 -> 0.60269862 | AA15: =luna16_k_fold_output!D13 -> 0.9130435 | AB15: =luna16_k_fold_output!E13 -> 0.19565217 | AC15: =luna16_k_fold_output!F13 -> 0.32225063 | AD15: =luna16_k_fold_output!G13 -> 0.78977406 | AE15: =luna16_k_fold_output!H13 -> 0.78692126 | AF15: =luna16_k_fold_output!I13 -> 339 | AG15: =luna16_k_fold_output!J13 -> 6 | ... AI15: =luna16_k_fold_output!L13 -> 63
A16: Medical-pretrained | B16: medicalnet | C16: 18 | D16: 1 | E16: =k_fold_output!C38 -> 26 | F16: =k_fold_output!D38 -> 0.86359763 | G16: =k_fold_output!E38 -> 0.37951806 | H16: =k_fold_output!F38 -> 0.52499998 | I16: =k_fold_output!G38 -> 0.44055945 | J16: =k_fold_output!H38 -> 0.82682806 | K16: =k_fold_output!I38 -> 0.37355745 | L16: =k_fold_output!J38 -> 950 | ... Y16: =k_fold_output!W38 -> 59 | Z16: =luna16_k_fold_output!C38 -> 0.64167917 | AA16: =luna16_k_fold_output!D38 -> 0.90291262 | AB16: =luna16_k_fold_output!E38 -> 0.28881988 | AC16: =luna16_k_fold_output!F38 -> 0.43764704 | AD16: =luna16_k_fold_output!G38 -> 0.76985323 | AE16: =luna16_k_fold_output!H38 -> 0.77507287 | AF16: =luna16_k_fold_output!I38 -> 335 | AG16: =luna16_k_fold_output!J38 -> 10 | ... AI16: =luna16_k_fold_output!L38 -> 93
D17: 2 | E17: =k_fold_output!C39 -> 37 | F17: =k_fold_output!D39 -> 0.92113823 | G17: =k_fold_output!E39 -> 0.62318838 | H17: =k_fold_output!F39 -> 0.37719297 | I17: =k_fold_output!G39 -> 0.46994534 | J17: =k_fold_output!H39 -> 0.88385057 | K17: =k_fold_output!I39 -> 0.53252614 | L17: =k_fold_output!J39 -> 1090 | ... Y17: =k_fold_output!W39 -> 22 | Z17: =luna16_k_fold_output!C39 -> 0.54872566 | AA17: =luna16_k_fold_output!D39 -> 0.95652175 | AB17: =luna16_k_fold_output!E39 -> 0.068322979 | AC17: =luna16_k_fold_output!F39 -> 0.12753624 | AD17: =luna16_k_fold_output!G39 -> 0.7590242 | AE17: =luna16_k_fold_output!H39 -> 0.7536661 | AF17: =luna16_k_fold_output!I39 -> 344 | AG17: =luna16_k_fold_output!J39 -> 1 | ... AI17: =luna16_k_fold_output!L39 -> 22
D18: 3 | E18: =k_fold_output!C40 -> 39 | F18: =k_fold_output!D40 -> 0.90575081 | G18: =k_fold_output!E40 -> 0.47008547 | H18: =k_fold_output!F40 -> 0.4954955 | I18: =k_fold_output!G40 -> 0.48245615 | J18: =k_fold_output!H40 -> 0.87084979 | K18: =k_fold_output!I40 -> 0.44323885 | L18: =k_fold_output!J40 -> 1079 | ... Y18: =k_fold_output!W40 -> 45 | Z18: =luna16_k_fold_output!C40 -> 0.64017993 | AA18: =luna16_k_fold_output!D40 -> 0.95555556 | AB18: =luna16_k_fold_output!E40 -> 0.26708075 | AC18: =luna16_k_fold_output!F40 -> 0.41747573 | AD18: =luna16_k_fold_output!G40 -> 0.79346472 | AE18: =luna16_k_fold_output!H40 -> 0.81275749 | AF18: =luna16_k_fold_output!I40 -> 341 | AG18: =luna16_k_fold_output!J40 -> 4 | ... AI18: =luna16_k_fold_output!L40 -> 86
D19: 4 | E19: =k_fold_output!C41 -> 42 | F19: =k_fold_output!D41 -> 0.89865994 | G19: =k_fold_output!E41 -> 0.42222223 | H19: =k_fold_output!F41 -> 0.56999999 | I19: =k_fold_output!G41 -> 0.48510638 | J19: =k_fold_output!H41 -> 0.87267822 | K19: =k_fold_output!I41 -> 0.54256165 | L19: =k_fold_output!J41 -> 1016 | ... Y19: =k_fold_output!W41 -> 50 | Z19: =luna16_k_fold_output!C41 -> 0.64167917 | AA19: =luna16_k_fold_output!D41 -> 0.86725664 | AB19: =luna16_k_fold_output!E41 -> 0.30434781 | AC19: =luna16_k_fold_output!F41 -> 0.45057473 | AD19: =luna16_k_fold_output!G41 -> 0.78220367 | AE19: =luna16_k_fold_output!H41 -> 0.78420681 | AF19: =luna16_k_fold_output!I41 -> 330 | AG19: =luna16_k_fold_output!J41 -> 15 | ... AI19: =luna16_k_fold_output!L41 -> 98
C20: 34 | D20: 1 | E20: =k_fold_output!C42 -> 33 | F20: =k_fold_output!D42 -> 0.89855075 | G20: =k_fold_output!E42 -> 0.50847459 | H20: =k_fold_output!F42 -> 0.25 | I20: =k_fold_output!G42 -> 0.33519554 | J20: =k_fold_output!H42 -> 0.84637541 | K20: =k_fold_output!I42 -> 0.42002362 | L20: =k_fold_output!J42 -> 1024 | ... Y20: =k_fold_output!W42 -> 32 | Z20: =luna16_k_fold_output!C42 -> 0.59520239 | AA20: =luna16_k_fold_output!D42 -> 1 | AB20: =luna16_k_fold_output!E42 -> 0.16149068 | AC20: =luna16_k_fold_output!F42 -> 0.27807486 | AD20: =luna16_k_fold_output!G42 -> 0.82657301 | AE20: =luna16_k_fold_output!H42 -> 0.8312391 | AF20: =luna16_k_fold_output!I42 -> 345 | AG20: =luna16_k_fold_output!J42 -> 0 | ... AI20: =luna16_k_fold_output!L42 -> 52
D21: 2 | E21: =k_fold_output!C43 -> 29 | F21: =k_fold_output!D43 -> 0.90569103 | G21: =k_fold_output!E43 -> 0.48333332 | H21: =k_fold_output!F43 -> 0.25438598 | I21: =k_fold_output!G43 -> 0.33333334 | J21: =k_fold_output!H43 -> 0.89451677 | K21: =k_fold_output!I43 -> 0.48057109 | L21: =k_fold_output!J43 -> 1085 | ... Y21: =k_fold_output!W43 -> 17 | Z21: =luna16_k_fold_output!C43 -> 0.55172414 | AA21: =luna16_k_fold_output!D43 -> 0.95999998 | AB21: =luna16_k_fold_output!E43 -> 0.074534163 | AC21: =luna16_k_fold_output!F43 -> 0.13832854 | AD21: =luna16_k_fold_output!G43 -> 0.76547837 | AE21: =luna16_k_fold_output!H43 -> 0.74337113 | AF21: =luna16_k_fold_output!I43 -> 344 | AG21: =luna16_k_fold_output!J43 -> 1 | ... AI21: =luna16_k_fold_output!L43 -> 24
D22: 3 | E22: =k_fold_output!C44 -> 45 | F22: =k_fold_output!D44 -> 0.87300318 | G22: =k_fold_output!E44 -> 0.34210527 | H22: =k_fold_output!F44 -> 0.46846846 | I22: =k_fold_output!G44 -> 0.39543727 | J22: =k_fold_output!H44 -> 0.84839439 | K22: =k_fold_output!I44 -> 0.35826829 | L22: =k_fold_output!J44 -> 1041 | ... Y22: =k_fold_output!W44 -> 61 | Z22: =luna16_k_fold_output!C44 -> 0.65367317 | AA22: =luna16_k_fold_output!D44 -> 0.86400002 | AB22: =luna16_k_fold_output!E44 -> 0.33540374 | AC22: =luna16_k_fold_output!F44 -> 0.48322147 | AD22: =luna16_k_fold_output!G44 -> 0.78241962 | AE22: =luna16_k_fold_output!H44 -> 0.76508671 | AF22: =luna16_k_fold_output!I44 -> 328 | AG22: =luna16_k_fold_output!J44 -> 17 | ... AI22: =luna16_k_fold_output!L44 -> 108
D23: 4 | E23: =k_fold_output!C45 -> 27 | F23: =k_fold_output!D45 -> 0.92797321 | G23: =k_fold_output!E45 -> 0.66666669 | H23: =k_fold_output!F45 -> 0.28 | I23: =k_fold_output!G45 -> 0.3943662 | J23: =k_fold_output!H45 -> 0.86474407 | K23: =k_fold_output!I45 -> 0.52845836 | L23: =k_fold_output!J45 -> 1080 | ... Y23: =k_fold_output!W45 -> 13 | Z23: =luna16_k_fold_output!C45 -> 0.55472267 | AA23: =luna16_k_fold_output!D45 -> 1 | AB23: =luna16_k_fold_output!E45 -> 0.077639751 | AC23: =luna16_k_fold_output!F45 -> 0.14409222 | AD23: =luna16_k_fold_output!G45 -> 0.81302547 | AE23: =luna16_k_fold_output!H45 -> 0.83590049 | AF23: =luna16_k_fold_output!I45 -> 345 | AG23: =luna16_k_fold_output!J45 -> 0 | ... AI23: =luna16_k_fold_output!L45 -> 25
C24: 50 | D24: 1 | E24: =k_fold_output!C46 -> 13 | F24: =k_fold_output!D46 -> 0.84825236 | G24: =k_fold_output!E46 -> 0.34574467 | H24: =k_fold_output!F46 -> 0.54166669 | I24: =k_fold_output!G46 -> 0.42207792 | J24: =k_fold_output!H46 -> 0.82881457 | K24: =k_fold_output!I46 -> 0.37043792 | L24: =k_fold_output!J46 -> 930 | ... Y24: =k_fold_output!W46 -> 61 | Z24: =luna16_k_fold_output!C46 -> 0.70764619 | AA24: =luna16_k_fold_output!D46 -> 0.90445858 | AB24: =luna16_k_fold_output!E46 -> 0.44099379 | AC24: =luna16_k_fold_output!F46 -> 0.59290189 | AD24: =luna16_k_fold_output!G46 -> 0.79089922 | AE24: =luna16_k_fold_output!H46 -> 0.8075844 | AF24: =luna16_k_fold_output!I46 -> 330 | AG24: =luna16_k_fold_output!J46 -> 15 | ... AI24: =luna16_k_fold_output!L46 -> 142
D25: 2 | E25: =k_fold_output!C47 -> 12 | F25: =k_fold_output!D47 -> 0.91300815 | G25: =k_fold_output!E47 -> 0.55737704 | H25: =k_fold_output!F47 -> 0.29824561 | I25: =k_fold_output!G47 -> 0.38857144 | J25: =k_fold_output!H47 -> 0.83639884 | K25: =k_fold_output!I47 -> 0.43921542 | L25: =k_fold_output!J47 -> 1089 | ... Y25: =k_fold_output!W47 -> 21 | Z25: =luna16_k_fold_output!C47 -> 0.56671667 | AA25: =luna16_k_fold_output!D47 -> 0.902439 | AB25: =luna16_k_fold_output!E47 -> 0.11490683 | AC25: =luna16_k_fold_output!F47 -> 0.20385675 | AD25: =luna16_k_fold_output!G47 -> 0.77810782 | AE25: =luna16_k_fold_output!H47 -> 0.7626282 | AF25: =luna16_k_fold_output!I47 -> 341 | AG25: =luna16_k_fold_output!J47 -> 4 | ... AI25: =luna16_k_fold_output!L47 -> 37
D26: 3 | E26: =k_fold_output!C48 -> 24 | F26: =k_fold_output!D48 -> 0.86661345 | G26: =k_fold_output!E48 -> 0.33529413 | H26: =k_fold_output!F48 -> 0.51351351 | I26: =k_fold_output!G48 -> 0.40569395 | J26: =k_fold_output!H48 -> 0.84645993 | K26: =k_fold_output!I48 -> 0.36728856 | L26: =k_fold_output!J48 -> 1028 | ... Y26: =k_fold_output!W48 -> 40 | Z26: =luna16_k_fold_output!C48 -> 0.6311844 | AA26: =luna16_k_fold_output!D48 -> 0.83333331 | AB26: =luna16_k_fold_output!E48 -> 0.29503107 | AC26: =luna16_k_fold_output!F48 -> 0.43577981 | AD26: =luna16_k_fold_output!G48 -> 0.75454134 | AE26: =luna16_k_fold_output!H48 -> 0.75094128 | AF26: =luna16_k_fold_output!I48 -> 326 | AG26: =luna16_k_fold_output!J48 -> 19 | ... AI26: =luna16_k_fold_output!L48 -> 95
D27: 4 | E27: =k_fold_output!C49 -> 24 | F27: =k_fold_output!D49 -> 0.91457283 | G27: =k_fold_output!E49 -> 0.49137932 | H27: =k_fold_output!F49 -> 0.56999999 | I27: =k_fold_output!G49 -> 0.52777779 | J27: =k_fold_output!H49 -> 0.89623398 | K27: =k_fold_output!I49 -> 0.50428051 | L27: =k_fold_output!J49 -> 1035 | ... Y27: =k_fold_output!W49 -> 42 | Z27: =luna16_k_fold_output!C49 -> 0.60569715 | AA27: =luna16_k_fold_output!D49 -> 0.81052631 | AB27: =luna16_k_fold_output!E49 -> 0.23913044 | AC27: =luna16_k_fold_output!F49 -> 0.36930457 | AD27: =luna16_k_fold_output!G49 -> 0.75329006 | AE27: =luna16_k_fold_output!H49 -> 0.7427938 | AF27: =luna16_k_fold_output!I49 -> 327 | AG27: =luna16_k_fold_output!J49 -> 18 | ... AI27: =luna16_k_fold_output!L49 -> 77
A28: Fresh | B28: resnet3d (1ch) | C28: 18 | D28: 1 | E28: =k_fold_output!C14 -> 18 | F28: =k_fold_output!D14 -> 0.85421997 | G28: =k_fold_output!E14 -> 0.3508772 | H28: =k_fold_output!F14 -> 0.5 | I28: =k_fold_output!G14 -> 0.41237113 | J28: =k_fold_output!H14 -> 0.82613963 | K28: =k_fold_output!I14 -> 0.37366024 | L28: =k_fold_output!J14 -> 942 | ... Y28: =k_fold_output!W14 -> 54 | Z28: =luna16_k_fold_output!C14 -> 0.68215895 | AA28: =luna16_k_fold_output!D14 -> 0.94354838 | AB28: =luna16_k_fold_output!E14 -> 0.36335403 | AC28: =luna16_k_fold_output!F14 -> 0.52466369 | AD28: =luna16_k_fold_output!G14 -> 0.83026373 | AE28: =luna16_k_fold_output!H14 -> 0.84052265 | AF28: =luna16_k_fold_output!I14 -> 338 | AG28: =luna16_k_fold_output!J14 -> 7 | ... AI28: =luna16_k_fold_output!L14 -> 117
D29: 2 | E29: =k_fold_output!C15 -> 4 | F29: =k_fold_output!D15 -> 0.88455284 | G29: =k_fold_output!E15 -> 0.38709676 | H29: =k_fold_output!F15 -> 0.42105263 | I29: =k_fold_output!G15 -> 0.40336135 | J29: =k_fold_output!H15 -> 0.85889453 | K29: =k_fold_output!I15 -> 0.35103896 | L29: =k_fold_output!J15 -> 1040 | ... Y29: =k_fold_output!W15 -> 44 | Z29: =luna16_k_fold_output!C15 -> 0.70464766 | AA29: =luna16_k_fold_output!D15 -> 0.95620435 | AB29: =luna16_k_fold_output!E15 -> 0.40683231 | AC29: =luna16_k_fold_output!F15 -> 0.57080609 | AD29: =luna16_k_fold_output!G15 -> 0.83759111 | AE29: =luna16_k_fold_output!H15 -> 0.86107492 | AF29: =luna16_k_fold_output!I15 -> 339 | AG29: =luna16_k_fold_output!J15 -> 6 | ... AI29: =luna16_k_fold_output!L15 -> 131
D30: 3 | E30: =k_fold_output!C16 -> 24 | F30: =k_fold_output!D16 -> 0.89057505 | G30: =k_fold_output!E16 -> 0.37962964 | H30: =k_fold_output!F16 -> 0.36936936 | I30: =k_fold_output!G16 -> 0.37442923 | J30: =k_fold_output!H16 -> 0.84608883 | K30: =k_fold_output!I16 -> 0.34211677 | L30: =k_fold_output!J16 -> 1074 | ... Y30: =k_fold_output!W16 -> 38 | Z30: =luna16_k_fold_output!C16 -> 0.66116941 | AA30: =luna16_k_fold_output!D16 -> 0.91379309 | AB30: =luna16_k_fold_output!E16 -> 0.32919255 | AC30: =luna16_k_fold_output!F16 -> 0.48401827 | AD30: =luna16_k_fold_output!G16 -> 0.81490684 | AE30: =luna16_k_fold_output!H16 -> 0.80393666 | AF30: =luna16_k_fold_output!I16 -> 335 | AG30: =luna16_k_fold_output!J16 -> 10 | ... AI30: =luna16_k_fold_output!L16 -> 106
D31: 4 | E31: =k_fold_output!C17 -> 29 | F31: =k_fold_output!D17 -> 0.90368509 | G31: =k_fold_output!E17 -> 0.43243244 | H31: =k_fold_output!F17 -> 0.47999999 | I31: =k_fold_output!G17 -> 0.45497629 | J31: =k_fold_output!H17 -> 0.86467093 | K31: =k_fold_output!I17 -> 0.49530852 | L31: =k_fold_output!J17 -> 1031 | ... Y31: =k_fold_output!W17 -> 47 | Z31: =luna16_k_fold_output!C17 -> 0.66416794 | AA31: =luna16_k_fold_output!D17 -> 0.9375 | AB31: =luna16_k_fold_output!E17 -> 0.32608697 | AC31: =luna16_k_fold_output!F17 -> 0.48387095 | AD31: =luna16_k_fold_output!G17 -> 0.82868844 | AE31: =luna16_k_fold_output!H17 -> 0.83844239 | AF31: =luna16_k_fold_output!I17 -> 338 | AG31: =luna16_k_fold_output!J17 -> 7 | ... AI31: =luna16_k_fold_output!L17 -> 105
C32: 34 | D32: 1 | E32: =k_fold_output!C22 -> 24 | F32: =k_fold_output!D22 -> 0.85592496 | G32: =k_fold_output!E22 -> 0.36158192 | H32: =k_fold_output!F22 -> 0.53333336 | I32: =k_fold_output!G22 -> 0.43097642 | J32: =k_fold_output!H22 -> 0.84165871 | K32: =k_fold_output!I22 -> 0.3704204 | L32: =k_fold_output!J22 -> 940 | ... Y32: =k_fold_output!W22 -> 67 | Z32: =luna16_k_fold_output!C18 -> 0.69115442 | AA32: =luna16_k_fold_output!D18 -> 0.92028987 | AB32: =luna16_k_fold_output!E18 -> 0.39440992 | AC32: =luna16_k_fold_output!F18 -> 0.55217391 | AD32: =luna16_k_fold_output!G18 -> 0.82170308 | AE32: =luna16_k_fold_output!H18 -> 0.84582829 | AF32: =luna16_k_fold_output!I18 -> 334 | AG32: =luna16_k_fold_output!J18 -> 11 | ... AI32: =luna16_k_fold_output!L18 -> 127
D33: 2 | E33: =k_fold_output!C23 -> 31 | F33: =k_fold_output!D23 -> 0.88617885 | G33: =k_fold_output!E23 -> 0.40972221 | H33: =k_fold_output!F23 -> 0.51754385 | I33: =k_fold_output!G23 -> 0.45736435 | J33: =k_fold_output!H23 -> 0.86739141 | K33: =k_fold_output!I23 -> 0.45576864 | L33: =k_fold_output!J23 -> 1031 | ... Y33: =k_fold_output!W23 -> 45 | Z33: =luna16_k_fold_output!C19 -> 0.68665665 | AA33: =luna16_k_fold_output!D19 -> 0.94488192 | AB33: =luna16_k_fold_output!E19 -> 0.3726708 | AC33: =luna16_k_fold_output!F19 -> 0.53452116 | AD33: =luna16_k_fold_output!G19 -> 0.84011161 | AE33: =luna16_k_fold_output!H19 -> 0.85692674 | AF33: =luna16_k_fold_output!I19 -> 338 | AG33: =luna16_k_fold_output!J19 -> 7 | ... AI33: =luna16_k_fold_output!L19 -> 120
D34: 3 | E34: =k_fold_output!C24 -> 45 | F34: =k_fold_output!D24 -> 0.90974438 | G34: =k_fold_output!E24 -> 0.49056605 | H34: =k_fold_output!F24 -> 0.46846846 | I34: =k_fold_output!G24 -> 0.47926268 | J34: =k_fold_output!H24 -> 0.85060513 | K34: =k_fold_output!I24 -> 0.44406235 | L34: =k_fold_output!J24 -> 1087 | ... Y34: =k_fold_output!W24 -> 42 | Z34: =luna16_k_fold_output!C20 -> 0.60569715 | AA34: =luna16_k_fold_output!D20 -> 0.9402985 | AB34: =luna16_k_fold_output!E20 -> 0.19565217 | AC34: =luna16_k_fold_output!F20 -> 0.32390746 | AD34: =luna16_k_fold_output!G20 -> 0.79760563 | AE34: =luna16_k_fold_output!H20 -> 0.80536586 | AF34: =luna16_k_fold_output!I20 -> 341 | AG34: =luna16_k_fold_output!J20 -> 4 | ... AI34: =luna16_k_fold_output!L20 -> 63
D35: 4 | E35: =k_fold_output!C25 -> 20 | F35: =k_fold_output!D25 -> 0.91038525 | G35: =k_fold_output!E25 -> 0.46464646 | H35: =k_fold_output!F25 -> 0.46000001 | I35: =k_fold_output!G25 -> 0.46231157 | J35: =k_fold_output!H25 -> 0.86663622 | K35: =k_fold_output!I25 -> 0.51087421 | L35: =k_fold_output!J25 -> 1041 | ... Y35: =k_fold_output!W25 -> 38 | Z35: =luna16_k_fold_output!C21 -> 0.73913044 | AA35: =luna16_k_fold_output!D21 -> 0.9512195 | AB35: =luna16_k_fold_output!E21 -> 0.48447204 | AC35: =luna16_k_fold_output!F21 -> 0.64197528 | AD35: =luna16_k_fold_output!G21 -> 0.84823114 | AE35: =luna16_k_fold_output!H21 -> 0.86757785 | AF35: =luna16_k_fold_output!I21 -> 337 | AG35: =luna16_k_fold_output!J21 -> 8 | ... AI35: =luna16_k_fold_output!L21 -> 156
C36: 50 | D36: 1 | E36: =k_fold_output!C30 -> 13 | F36: =k_fold_output!D30 -> 0.86530262 | G36: =k_fold_output!E30 -> 0.37333333 | H36: =k_fold_output!F30 -> 0.46666667 | I36: =k_fold_output!G30 -> 0.4148148 | J36: =k_fold_output!H30 -> 0.82583892 | K36: =k_fold_output!I30 -> 0.42227468 | L36: =k_fold_output!J30 -> 959 | ... Y36: =k_fold_output!W30 -> 58 | Z36: =luna16_k_fold_output!C22 -> 0.70614696 | AA36: =luna16_k_fold_output!D22 -> 0.88414633 | AB36: =luna16_k_fold_output!E22 -> 0.45031056 | AC36: =luna16_k_fold_output!F22 -> 0.59670782 | AD36: =luna16_k_fold_output!G22 -> 0.82557386 | AE36: =luna16_k_fold_output!H22 -> 0.81472784 | AF36: =luna16_k_fold_output!I22 -> 326 | AG36: =luna16_k_fold_output!J22 -> 19 | ... AI36: =luna16_k_fold_output!L22 -> 145
D37: 2 | E37: =k_fold_output!C31 -> 25 | F37: =k_fold_output!D31 -> 0.89999998 | G37: =k_fold_output!E31 -> 0.44 | H37: =k_fold_output!F31 -> 0.28947368 | I37: =k_fold_output!G31 -> 0.34920636 | J37: =k_fold_output!H31 -> 0.85023266 | K37: =k_fold_output!I31 -> 0.41191569 | L37: =k_fold_output!J31 -> 1074 | ... Y37: =k_fold_output!W31 -> 35 | Z37: =luna16_k_fold_output!C23 -> 0.67766118 | AA37: =luna16_k_fold_output!D23 -> 0.89051098 | AB37: =luna16_k_fold_output!E23 -> 0.37888199 | AC37: =luna16_k_fold_output!F23 -> 0.5315904 | AD37: =luna16_k_fold_output!G23 -> 0.79344678 | AE37: =luna16_k_fold_output!H23 -> 0.81689566 | AF37: =luna16_k_fold_output!I23 -> 330 | AG37: =luna16_k_fold_output!J23 -> 15 | ... AI37: =luna16_k_fold_output!L23 -> 122
D38: 3 | E38: =k_fold_output!C32 -> 29 | F38: =k_fold_output!D32 -> 0.89856231 | G38: =k_fold_output!E32 -> 0.40697673 | H38: =k_fold_output!F32 -> 0.31531531 | I38: =k_fold_output!G32 -> 0.35532996 | J38: =k_fold_output!H32 -> 0.84073555 | K38: =k_fold_output!I32 -> 0.41208741 | L38: =k_fold_output!J32 -> 1090 | ... Y38: =k_fold_output!W32 -> 32 | Z38: =luna16_k_fold_output!C24 -> 0.63868064 | AA38: =luna16_k_fold_output!D24 -> 0.90099013 | AB38: =luna16_k_fold_output!E24 -> 0.28260869 | AC38: =luna16_k_fold_output!F24 -> 0.43026003 | AD38: =luna16_k_fold_output!G24 -> 0.75936627 | AE38: =luna16_k_fold_output!H24 -> 0.78163183 | AF38: =luna16_k_fold_output!I24 -> 335 | AG38: =luna16_k_fold_output!J24 -> 10 | ... AI38: =luna16_k_fold_output!L24 -> 91
D39: 4 | E39: =k_fold_output!C33 -> 16 | F39: =k_fold_output!D33 -> 0.91708541 | G39: =k_fold_output!E33 -> 0.50588238 | H39: =k_fold_output!F33 -> 0.43000001 | I39: =k_fold_output!G33 -> 0.46486485 | J39: =k_fold_output!H33 -> 0.88147175 | K39: =k_fold_output!I33 -> 0.49897057 | L39: =k_fold_output!J33 -> 1052 | ... Y39: =k_fold_output!W33 -> 35 | Z39: =luna16_k_fold_output!C25 -> 0.65067464 | AA39: =luna16_k_fold_output!D25 -> 0.98901099 | AB39: =luna16_k_fold_output!E25 -> 0.27950311 | AC39: =luna16_k_fold_output!F25 -> 0.43583536 | AD39: =luna16_k_fold_output!G25 -> 0.82860744 | AE39: =luna16_k_fold_output!H25 -> 0.85883534 | AF39: =luna16_k_fold_output!I25 -> 344 | AG39: =luna16_k_fold_output!J25 -> 1 | ... AI39: =luna16_k_fold_output!L25 -> 90
A40: Fresh | B40: resnet3d (3ch) | C40: 18 | D40: 1 | E40: =k_fold_output!C18 -> 11 | F40: =k_fold_output!D18 -> 0.8678602 | G40: =k_fold_output!E18 -> 0.38410595 | H40: =k_fold_output!F18 -> 0.48333332 | I40: =k_fold_output!G18 -> 0.42804429 | J40: =k_fold_output!H18 -> 0.84235513 | K40: =k_fold_output!I18 -> 0.39759558 | L40: =k_fold_output!J18 -> 960 | ... Y40: =k_fold_output!W18 -> 48 | Z40: =luna16_k_fold_output!C26 -> 0.70914543 | AA40: =luna16_k_fold_output!D26 -> 0.92105263 | AB40: =luna16_k_fold_output!E26 -> 0.43478259 | AC40: =luna16_k_fold_output!F26 -> 0.59071732 | AD40: =luna16_k_fold_output!G26 -> 0.8439554 | AE40: =luna16_k_fold_output!H26 -> 0.84806091 | AF40: =luna16_k_fold_output!I26 -> 333 | AG40: =luna16_k_fold_output!J26 -> 12 | ... AI40: =luna16_k_fold_output!L26 -> 140
...

Sheet Subsheet
A1: Type | B1: Model | D1: Fold | E1: Best Epoch | F1: Validation | L1: Test | R1: External (LUNA16)
B2: Name | C2: Depth | F2: Accuracy | G2: Precision | H2: Recall | I2: F1 | J2: AUROC | K2: AP | L2: Accuracy | M2: Precision | N2: Recall | O2: F1 | P2: AUROC | Q2: AP | R2: Accuracy | S2: Precision | T2: Recall | U2: F1 | V2: AUROC | W2: AP
A4: Fresh | B4: medicalnet | C4: 18 | D4: 1 | E4: ='Main Sheet'!E4 -> 34 | F4: ='Main Sheet'!F4 -> 0.84313726 | G4: ='Main Sheet'!G4 -> 0.32417583 | H4: ='Main Sheet'!H4 -> 0.49166667 | I4: ='Main Sheet'!I4 -> 0.39072847 | J4: ='Main Sheet'!J4 -> 0.82061577 | K4: ='Main Sheet'!K4 -> 0.29654428 | L4: ='Main Sheet'!P4 -> 0.86605781 | M4: ='Main Sheet'!Q4 -> 0.32258064 | N4: ='Main Sheet'!R4 -> 0.54545456 | O4: ='Main Sheet'!S4 -> 0.4054054 | P4: ='Main Sheet'!T4 -> 0.84757626 | Q4: ='Main Sheet'!U4 -> 0.37488148 | R4: ='Main Sheet'!Z4 -> 0.69565219 | S4: ='Main Sheet'!AA4 -> 0.94736844 | T4: ='Main Sheet'!AB4 -> 0.39130434 | U4: ='Main Sheet'!AC4 -> 0.55384618 | V4: ='Main Sheet'!AD4 -> 0.81092805 | W4: ='Main Sheet'!AE4 -> 0.83184785
D5: 2 | E5: ='Main Sheet'!E5 -> 24 | F5: ='Main Sheet'!F5 -> 0.87479675 | G5: ='Main Sheet'!G5 -> 0.38636363 | H5: ='Main Sheet'!H5 -> 0.59649122 | I5: ='Main Sheet'!I5 -> 0.46896553 | J5: ='Main Sheet'!J5 -> 0.88657022 | K5: ='Main Sheet'!K5 -> 0.47210073 | L5: ='Main Sheet'!P5 -> 0.83789957 | M5: ='Main Sheet'!Q5 -> 0.25821596 | N5: ='Main Sheet'!R5 -> 0.5 | O5: ='Main Sheet'!S5 -> 0.34055728 | P5: ='Main Sheet'!T5 -> 0.78593332 | Q5: ='Main Sheet'!U5 -> 0.29977146 | R5: ='Main Sheet'!Z5 -> 0.66866565 | S5: ='Main Sheet'!AA5 -> 0.85314685 | T5: ='Main Sheet'!AB5 -> 0.37888199 | U5: ='Main Sheet'!AC5 -> 0.52473116 | V5: ='Main Sheet'!AD5 -> 0.75666571 | W5: ='Main Sheet'!AE5 -> 0.77139533
D6: 3 | E6: ='Main Sheet'!E6 -> 36 | F6: ='Main Sheet'!F6 -> 0.88258785 | G6: ='Main Sheet'!G6 -> 0.34482759 | H6: ='Main Sheet'!H6 -> 0.36036035 | I6: ='Main Sheet'!I6 -> 0.35242289 | J6: ='Main Sheet'!J6 -> 0.83903003 | K6: ='Main Sheet'!K6 -> 0.36322302 | L6: ='Main Sheet'!P6 -> 0.87899542 | M6: ='Main Sheet'!Q6 -> 0.33986929 | N6: ='Main Sheet'!R6 -> 0.47272727 | O6: ='Main Sheet'!S6 -> 0.39543727 | P6: ='Main Sheet'!T6 -> 0.81479156 | Q6: ='Main Sheet'!U6 -> 0.29309142 | R6: ='Main Sheet'!Z6 -> 0.61169416 | S6: ='Main Sheet'!AA6 -> 0.86206895 | T6: ='Main Sheet'!AB6 -> 0.23291926 | U6: ='Main Sheet'!AC6 -> 0.36674815 | V6: ='Main Sheet'!AD6 -> 0.75101274 | W6: ='Main Sheet'!AE6 -> 0.74560064
D7: 4 | E7: ='Main Sheet'!E7 -> 34 | F7: ='Main Sheet'!F7 -> 0.8768844 | G7: ='Main Sheet'!G7 -> 0.37016574 | H7: ='Main Sheet'!H7 -> 0.67000002 | I7: ='Main Sheet'!I7 -> 0.47686833 | J7: ='Main Sheet'!J7 -> 0.87851006 | K7: ='Main Sheet'!K7 -> 0.55413777 | L7: ='Main Sheet'!P7 -> 0.84474885 | M7: ='Main Sheet'!Q7 -> 0.29565218 | N7: ='Main Sheet'!R7 -> 0.61818182 | O7: ='Main Sheet'!S7 -> 0.40000001 | P7: ='Main Sheet'!T7 -> 0.85419059 | Q7: ='Main Sheet'!U7 -> 0.35654956 | R7: ='Main Sheet'!Z7 -> 0.70014995 | S7: ='Main Sheet'!AA7 -> 0.88125002 | T7: ='Main Sheet'!AB7 -> 0.43788821 | U7: ='Main Sheet'!AC7 -> 0.58506227 | V7: ='Main Sheet'!AD7 -> 0.78428298 | W7: ='Main Sheet'!AE7 -> 0.80389529
C8: 34 | D8: 1 | E8: ='Main Sheet'!E8 -> 47 | F8: ='Main Sheet'!F8 -> 0.86104006 | G8: ='Main Sheet'!G8 -> 0.37572256 | H8: ='Main Sheet'!H8 -> 0.54166669 | I8: ='Main Sheet'!I8 -> 0.44368601 | J8: ='Main Sheet'!J8 -> 0.8345679 | K8: ='Main Sheet'!K8 -> 0.4107185 | L8: ='Main Sheet'!P8 -> 0.86529678 | M8: ='Main Sheet'!Q8 -> 0.31693989 | N8: ='Main Sheet'!R8 -> 0.5272727 | O8: ='Main Sheet'!S8 -> 0.39590445 | P8: ='Main Sheet'!T8 -> 0.84269857 | Q8: ='Main Sheet'!U8 -> 0.35345256 | R8: ='Main Sheet'!Z8 -> 0.69115442 | S8: ='Main Sheet'!AA8 -> 0.8918919 | T8: ='Main Sheet'!AB8 -> 0.40993789 | U8: ='Main Sheet'!AC8 -> 0.56170213 | V8: ='Main Sheet'!AD8 -> 0.79862279 | W8: ='Main Sheet'!AE8 -> 0.80966544
D9: 2 | E9: ='Main Sheet'!E9 -> 46 | F9: ='Main Sheet'!F9 -> 0.91707319 | G9: ='Main Sheet'!G9 -> 0.57317072 | H9: ='Main Sheet'!H9 -> 0.41228071 | I9: ='Main Sheet'!I9 -> 0.47959185 | J9: ='Main Sheet'!J9 -> 0.88806361 | K9: ='Main Sheet'!K9 -> 0.51720136 | L9: ='Main Sheet'!P9 -> 0.89726025 | M9: ='Main Sheet'!Q9 -> 0.32394367 | N9: ='Main Sheet'!R9 -> 0.2090909 | O9: ='Main Sheet'!S9 -> 0.25414366 | P9: ='Main Sheet'!T9 -> 0.78586531 | Q9: ='Main Sheet'!U9 -> 0.27040511 | R9: ='Main Sheet'!Z9 -> 0.57571214 | S9: ='Main Sheet'!AA9 -> 0.88235295 | T9: ='Main Sheet'!AB9 -> 0.13975155 | U9: ='Main Sheet'!AC9 -> 0.24128686 | V9: ='Main Sheet'!AD9 -> 0.74853724 | W9: ='Main Sheet'!AE9 -> 0.74480987
D10: 3 | E10: ='Main Sheet'!E10 -> 22 | F10: ='Main Sheet'!F10 -> 0.88658148 | G10: ='Main Sheet'!G10 -> 0.37190083 | H10: ='Main Sheet'!H10 -> 0.4054054 | I10: ='Main Sheet'!I10 -> 0.38793105 | J10: ='Main Sheet'!J10 -> 0.84649146 | K10: ='Main Sheet'!K10 -> 0.33777294 | L10: ='Main Sheet'!P10 -> 0.87975645 | M10: ='Main Sheet'!Q10 -> 0.30645162 | N10: ='Main Sheet'!R10 -> 0.34545454 | O10: ='Main Sheet'!S10 -> 0.32478634 | P10: ='Main Sheet'!T10 -> 0.81576556 | Q10: ='Main Sheet'!U10 -> 0.30284184 | R10: ='Main Sheet'!Z10 -> 0.66416794 | S10: ='Main Sheet'!AA10 -> 0.90163934 | T10: ='Main Sheet'!AB10 -> 0.3416149 | U10: ='Main Sheet'!AC10 -> 0.4954955 | V10: ='Main Sheet'!AD10 -> 0.81018096 | W10: ='Main Sheet'!AE10 -> 0.80914408
D11: 4 | E11: ='Main Sheet'!E11 -> 43 | F11: ='Main Sheet'!F11 -> 0.92294806 | G11: ='Main Sheet'!G11 -> 0.55714285 | H11: ='Main Sheet'!H11 -> 0.38999999 | I11: ='Main Sheet'!I11 -> 0.45882353 | J11: ='Main Sheet'!J11 -> 0.86962527 | K11: ='Main Sheet'!K11 -> 0.4858034 | L11: ='Main Sheet'!P11 -> 0.89117199 | M11: ='Main Sheet'!Q11 -> 0.24615385 | N11: ='Main Sheet'!R11 -> 0.14545454 | O11: ='Main Sheet'!S11 -> 0.18285714 | P11: ='Main Sheet'!T11 -> 0.83652973 | Q11: ='Main Sheet'!U11 -> 0.27166513 | R11: ='Main Sheet'!Z11 -> 0.58770615 | S11: ='Main Sheet'!AA11 -> 0.89830506 | T11: ='Main Sheet'!AB11 -> 0.16459627 | U11: ='Main Sheet'!AC11 -> 0.27821523 | V11: ='Main Sheet'!AD11 -> 0.75701684 | W11: ='Main Sheet'!AE11 -> 0.76895565
C12: 50 | D12: 1 | E12: ='Main Sheet'!E12 -> 28 | F12: ='Main Sheet'!F12 -> 0.89002556 | G12: ='Main Sheet'!G12 -> 0.45945945 | H12: ='Main Sheet'!H12 -> 0.42500001 | I12: ='Main Sheet'!I12 -> 0.44155845 | J12: ='Main Sheet'!J12 -> 0.83556497 | K12: ='Main Sheet'!K12 -> 0.42802811 | L12: ='Main Sheet'!P12 -> 0.89345509 | M12: ='Main Sheet'!Q12 -> 0.3828125 | N12: ='Main Sheet'!R12 -> 0.44545454 | O12: ='Main Sheet'!S12 -> 0.41176471 | P12: ='Main Sheet'!T12 -> 0.85384315 | Q12: ='Main Sheet'!U12 -> 0.37506282 | R12: ='Main Sheet'!Z12 -> 0.64767617 | S12: ='Main Sheet'!AA12 -> 0.96774191 | T12: ='Main Sheet'!AB12 -> 0.27950311 | U12: ='Main Sheet'!AC12 -> 0.43373495 | V12: ='Main Sheet'!AD12 -> 0.78731662 | W12: ='Main Sheet'!AE12 -> 0.81632018
D13: 2 | E13: ='Main Sheet'!E13 -> 9 | F13: ='Main Sheet'!F13 -> 0.90894312 | G13: ='Main Sheet'!G13 -> 0.51190478 | H13: ='Main Sheet'!H13 -> 0.37719297 | I13: ='Main Sheet'!I13 -> 0.43434343 | J13: ='Main Sheet'!J13 -> 0.88175189 | K13: ='Main Sheet'!K13 -> 0.45915222 | L13: ='Main Sheet'!P13 -> 0.90258753 | M13: ='Main Sheet'!Q13 -> 0.39024389 | N13: ='Main Sheet'!R13 -> 0.29090908 | O13: ='Main Sheet'!S13 -> 0.33333334 | P13: ='Main Sheet'!T13 -> 0.8528617 | Q13: ='Main Sheet'!U13 -> 0.33635324 | R13: ='Main Sheet'!Z13 -> 0.57871062 | S13: ='Main Sheet'!AA13 -> 0.97674417 | T13: ='Main Sheet'!AB13 -> 0.13043478 | U13: ='Main Sheet'!AC13 -> 0.23013699 | V13: ='Main Sheet'!AD13 -> 0.77729768 | W13: ='Main Sheet'!AE13 -> 0.80045927
D14: 3 | E14: ='Main Sheet'!E14 -> 18 | F14: ='Main Sheet'!F14 -> 0.90575081 | G14: ='Main Sheet'!G14 -> 0.45333335 | H14: ='Main Sheet'!H14 -> 0.3063063 | I14: ='Main Sheet'!I14 -> 0.36559141 | J14: ='Main Sheet'!J14 -> 0.82869464 | K14: ='Main Sheet'!K14 -> 0.39162976 | L14: ='Main Sheet'!P14 -> 0.9041096 | M14: ='Main Sheet'!Q14 -> 0.37096775 | N14: ='Main Sheet'!R14 -> 0.2090909 | O14: ='Main Sheet'!S14 -> 0.26744187 | P14: ='Main Sheet'!T14 -> 0.84774995 | Q14: ='Main Sheet'!U14 -> 0.32019734 | R14: ='Main Sheet'!Z14 -> 0.57271361 | S14: ='Main Sheet'!AA14 -> 0.91111112 | T14: ='Main Sheet'!AB14 -> 0.12732919 | U14: ='Main Sheet'!AC14 -> 0.22343324 | V14: ='Main Sheet'!AD14 -> 0.7817986 | W14: ='Main Sheet'!AE14 -> 0.77736735
D15: 4 | E15: ='Main Sheet'!E15 -> 16 | F15: ='Main Sheet'!F15 -> 0.89782244 | G15: ='Main Sheet'!G15 -> 0.40983605 | H15: ='Main Sheet'!H15 -> 0.5 | I15: ='Main Sheet'!I15 -> 0.45045045 | J15: ='Main Sheet'!J15 -> 0.86980808 | K15: ='Main Sheet'!K15 -> 0.52274638 | L15: ='Main Sheet'!P15 -> 0.90639269 | M15: ='Main Sheet'!Q15 -> 0.44144145 | N15: ='Main Sheet'!R15 -> 0.44545454 | O15: ='Main Sheet'!S15 -> 0.44343892 | P15: ='Main Sheet'!T15 -> 0.85299003 | Q15: ='Main Sheet'!U15 -> 0.40562862 | R15: ='Main Sheet'!Z15 -> 0.60269862 | S15: ='Main Sheet'!AA15 -> 0.9130435 | T15: ='Main Sheet'!AB15 -> 0.19565217 | U15: ='Main Sheet'!AC15 -> 0.32225063 | V15: ='Main Sheet'!AD15 -> 0.78977406 | W15: ='Main Sheet'!AE15 -> 0.78692126
A16: Medical-pretrained | B16: medicalnet | C16: 18 | D16: 1 | E16: ='Main Sheet'!E16 -> 26 | F16: ='Main Sheet'!F16 -> 0.86359763 | G16: ='Main Sheet'!G16 -> 0.37951806 | H16: ='Main Sheet'!H16 -> 0.52499998 | I16: ='Main Sheet'!I16 -> 0.44055945 | J16: ='Main Sheet'!J16 -> 0.82682806 | K16: ='Main Sheet'!K16 -> 0.37355745 | L16: ='Main Sheet'!P16 -> 0.86225265 | M16: ='Main Sheet'!Q16 -> 0.31216931 | N16: ='Main Sheet'!R16 -> 0.53636366 | O16: ='Main Sheet'!S16 -> 0.39464882 | P16: ='Main Sheet'!T16 -> 0.81551653 | Q16: ='Main Sheet'!U16 -> 0.35379672 | R16: ='Main Sheet'!Z16 -> 0.64167917 | S16: ='Main Sheet'!AA16 -> 0.90291262 | T16: ='Main Sheet'!AB16 -> 0.28881988 | U16: ='Main Sheet'!AC16 -> 0.43764704 | V16: ='Main Sheet'!AD16 -> 0.76985323 | W16: ='Main Sheet'!AE16 -> 0.77507287
D17: 2 | E17: ='Main Sheet'!E17 -> 37 | F17: ='Main Sheet'!F17 -> 0.92113823 | G17: ='Main Sheet'!G17 -> 0.62318838 | H17: ='Main Sheet'!H17 -> 0.37719297 | I17: ='Main Sheet'!I17 -> 0.46994534 | J17: ='Main Sheet'!J17 -> 0.88385057 | K17: ='Main Sheet'!K17 -> 0.53252614 | L17: ='Main Sheet'!P17 -> 0.91095889 | M17: ='Main Sheet'!Q17 -> 0.43137255 | N17: ='Main Sheet'!R17 -> 0.2 | O17: ='Main Sheet'!S17 -> 0.27329192 | P17: ='Main Sheet'!T17 -> 0.82139087 | Q17: ='Main Sheet'!U17 -> 0.32400599 | R17: ='Main Sheet'!Z17 -> 0.54872566 | S17: ='Main Sheet'!AA17 -> 0.95652175 | T17: ='Main Sheet'!AB17 -> 0.068322979 | U17: ='Main Sheet'!AC17 -> 0.12753624 | V17: ='Main Sheet'!AD17 -> 0.7590242 | W17: ='Main Sheet'!AE17 -> 0.7536661
D18: 3 | E18: ='Main Sheet'!E18 -> 39 | F18: ='Main Sheet'!F18 -> 0.90575081 | G18: ='Main Sheet'!G18 -> 0.47008547 | H18: ='Main Sheet'!H18 -> 0.4954955 | I18: ='Main Sheet'!I18 -> 0.48245615 | J18: ='Main Sheet'!J18 -> 0.87084979 | K18: ='Main Sheet'!K18 -> 0.44323885 | L18: ='Main Sheet'!P18 -> 0.88051748 | M18: ='Main Sheet'!Q18 -> 0.32846716 | N18: ='Main Sheet'!R18 -> 0.40909091 | O18: ='Main Sheet'!S18 -> 0.36437246 | P18: ='Main Sheet'!T18 -> 0.83143306 | Q18: ='Main Sheet'!U18 -> 0.31813473 | R18: ='Main Sheet'!Z18 -> 0.64017993 | S18: ='Main Sheet'!AA18 -> 0.95555556 | T18: ='Main Sheet'!AB18 -> 0.26708075 | U18: ='Main Sheet'!AC18 -> 0.41747573 | V18: ='Main Sheet'!AD18 -> 0.79346472 | W18: ='Main Sheet'!AE18 -> 0.81275749
D19: 4 | E19: ='Main Sheet'!E19 -> 42 | F19: ='Main Sheet'!F19 -> 0.89865994 | G19: ='Main Sheet'!G19 -> 0.42222223 | H19: ='Main Sheet'!H19 -> 0.56999999 | I19: ='Main Sheet'!I19 -> 0.48510638 | J19: ='Main Sheet'!J19 -> 0.87267822 | K19: ='Main Sheet'!K19 -> 0.54256165 | L19: ='Main Sheet'!P19 -> 0.88051748 | M19: ='Main Sheet'!Q19 -> 0.34013605 | N19: ='Main Sheet'!R19 -> 0.45454547 | O19: ='Main Sheet'!S19 -> 0.38910505 | P19: ='Main Sheet'!T19 -> 0.85246909 | Q19: ='Main Sheet'!U19 -> 0.37204933 | R19: ='Main Sheet'!Z19 -> 0.64167917 | S19: ='Main Sheet'!AA19 -> 0.86725664 | T19: ='Main Sheet'!AB19 -> 0.30434781 | U19: ='Main Sheet'!AC19 -> 0.45057473 | V19: ='Main Sheet'!AD19 -> 0.78220367 | W19: ='Main Sheet'!AE19 -> 0.78420681
C20: 34 | D20: 1 | E20: ='Main Sheet'!E20 -> 33 | F20: ='Main Sheet'!F20 -> 0.89855075 | G20: ='Main Sheet'!G20 -> 0.50847459 | H20: ='Main Sheet'!H20 -> 0.25 | I20: ='Main Sheet'!I20 -> 0.33519554 | J20: ='Main Sheet'!J20 -> 0.84637541 | K20: ='Main Sheet'!K20 -> 0.42002362 | L20: ='Main Sheet'!P20 -> 0.91400301 | M20: ='Main Sheet'!Q20 -> 0.47761193 | N20: ='Main Sheet'!R20 -> 0.29090908 | O20: ='Main Sheet'!S20 -> 0.36158192 | P20: ='Main Sheet'!T20 -> 0.83520079 | Q20: ='Main Sheet'!U20 -> 0.38183352 | R20: ='Main Sheet'!Z20 -> 0.59520239 | S20: ='Main Sheet'!AA20 -> 1 | T20: ='Main Sheet'!AB20 -> 0.16149068 | U20: ='Main Sheet'!AC20 -> 0.27807486 | V20: ='Main Sheet'!AD20 -> 0.82657301 | W20: ='Main Sheet'!AE20 -> 0.8312391
D21: 2 | E21: ='Main Sheet'!E21 -> 29 | F21: ='Main Sheet'!F21 -> 0.90569103 | G21: ='Main Sheet'!G21 -> 0.48333332 | H21: ='Main Sheet'!H21 -> 0.25438598 | I21: ='Main Sheet'!I21 -> 0.33333334 | J21: ='Main Sheet'!J21 -> 0.89451677 | K21: ='Main Sheet'!K21 -> 0.48057109 | L21: ='Main Sheet'!P21 -> 0.90639269 | M21: ='Main Sheet'!Q21 -> 0.36170211 | N21: ='Main Sheet'!R21 -> 0.15454546 | O21: ='Main Sheet'!S21 -> 0.21656051 | P21: ='Main Sheet'!T21 -> 0.82518119 | Q21: ='Main Sheet'!U21 -> 0.26359782 | R21: ='Main Sheet'!Z21 -> 0.55172414 | S21: ='Main Sheet'!AA21 -> 0.95999998 | T21: ='Main Sheet'!AB21 -> 0.074534163 | U21: ='Main Sheet'!AC21 -> 0.13832854 | V21: ='Main Sheet'!AD21 -> 0.76547837 | W21: ='Main Sheet'!AE21 -> 0.74337113
D22: 3 | E22: ='Main Sheet'!E22 -> 45 | F22: ='Main Sheet'!F22 -> 0.87300318 | G22: ='Main Sheet'!G22 -> 0.34210527 | H22: ='Main Sheet'!H22 -> 0.46846846 | I22: ='Main Sheet'!I22 -> 0.39543727 | J22: ='Main Sheet'!J22 -> 0.84839439 | K22: ='Main Sheet'!K22 -> 0.35826829 | L22: ='Main Sheet'!P22 -> 0.88051748 | M22: ='Main Sheet'!Q22 -> 0.36094674 | N22: ='Main Sheet'!R22 -> 0.55454546 | O22: ='Main Sheet'!S22 -> 0.43727598 | P22: ='Main Sheet'!T22 -> 0.86955595 | Q22: ='Main Sheet'!U22 -> 0.3869445 | R22: ='Main Sheet'!Z22 -> 0.65367317 | S22: ='Main Sheet'!AA22 -> 0.86400002 | T22: ='Main Sheet'!AB22 -> 0.33540374 | U22: ='Main Sheet'!AC22 -> 0.48322147 | V22: ='Main Sheet'!AD22 -> 0.78241962 | W22: ='Main Sheet'!AE22 -> 0.76508671
